<?xml version="1.0"?>
<robot xmlns:xacro="http://ros.org/wiki/xacro">
  <material name="blue">
    <color rgba="0 0 1 1"/>
  </material>
  <material name="red">
    <color rgba="1 0 0 1"/>
  </material>
  <material name="green">
    <color rgba="0 1 0 1"/>
  </material>
  <material name="black">
    <color rgba="0 0 0 1"/>
  </material>
  <material name="white">
    <color rgba="1 1 1 1"/>
  </material>
  <xacro:property name="scale" value="1.0 1.0 1.0"/>
  
  <xacro:macro name="base_link" params="namex">
    <link name="${namex}">
      <visual>
        <geometry>
          <mesh filename="package://gripper-rollpawkit/meshes/joint_connector.stl"/>
        </geometry>
        <material name="white"/>
      </visual>
      <visual>
        <origin xyz="0.0174 0 0" />
        <geometry>
          <mesh filename="package://gripper-rollpawkit/meshes/servo_plate.stl"/>
        </geometry>
        <material name="white"/>
      </visual>
      <collision>
        <geometry>
          <mesh filename="package://gripper-rollpawkit/meshes/joint_connector.stl"/>
        </geometry>
      </collision>
      <collision>
        <geometry>
          <mesh filename="package://gripper-rollpawkit/meshes/servo_plate.stl"/>
        </geometry>
      </collision>
    </link>
  </xacro:macro>

  <!-- Gears -->
  
  <xacro:macro name="gear_link" params="namex mesh">
    <link name="${namex}">
      <visual>
        <geometry>
          <mesh filename="${mesh}"/>
        </geometry>
        <material name="white"/>
      </visual>
      <collision>
        <geometry>
          <mesh filename="${mesh}"/>
        </geometry>
      </collision>
    </link>
  </xacro:macro>

  <xacro:macro name="gear_joint" params="namex parentx childx origin mimicx:='' lo:=0 hi:=0">
    <joint name="${namex}" type="revolute">
      <origin xyz="${origin}" rpy="0 0 0"/>
      <parent link="${parentx}" />
      <child link="${childx}" />
      <axis xyz="0 0 1" />
      <limit lower="${lo}" upper="${hi}" velocity="2.0" effort="1000" />
      <xacro:if value="${mimicx != ''}">
        <mimic joint="${mimicx}" multiplier="-1" offset="0" />
      </xacro:if>
    </joint>
  </xacro:macro>

  <!-- Gear linkage -->
  
  <xacro:macro name="gear_linkage_link" params="namex mesh">
    <link name="${namex}">
      <visual>
        <geometry>
          <mesh filename="${mesh}"/>
        </geometry>
        <material name="white"/>
      </visual>
      <collision>
        <geometry>
          <mesh filename="${mesh}"/>
        </geometry>
      </collision>
    </link>
  </xacro:macro>

  <xacro:macro name="gear_linkage_joint" params="namex parentx childx origin mimicx">
    <joint name="${namex}" type="revolute">
      <origin xyz="${origin}" rpy="0 0 0"/>
      <parent link="${parentx}" />
      <child link="${childx}" />
      <axis xyz="0 0 1" />
      <limit lower="0" upper="0.81" velocity="2.0" effort="1000" />
      <mimic joint="${mimicx}" multiplier="1" offset="0" />
    </joint>
  </xacro:macro>

  <!-- Finger linkage -->
  
  <xacro:macro name="finger_link" params="namex rpyx mesh">
    <link name="${namex}">
      <visual>
        <origin rpy="${rpyx}"/>
        <geometry>
          <mesh filename="${mesh}"/>
        </geometry>
        <material name="white"/>
      </visual>
      <collision>
        <origin rpy="${rpyx}"/>
        <geometry>
          <mesh filename="${mesh}"/>
        </geometry>
      </collision>
    </link>
  </xacro:macro>

  <xacro:macro name="finger_joint" params="namex parentx childx origin lo:=0 hi:=0 offset mimicx">
    <joint name="${namex}" type="revolute">
      <origin xyz="${origin}" rpy="0 0 0"/>
      <parent link="${parentx}" />
      <child link="${childx}" />
      <axis xyz="0 0 1" />
      <limit lower="${lo}" upper="${hi}" velocity="2.0" effort="1000" />
      <mimic joint="${mimicx}" multiplier="-1" offset="${offset}" />
    </joint>
  </xacro:macro>
  
  <!-- Initialization of all joints and links -->
  
  <xacro:macro name="gripper-rollpawkit" params="prefix">
    <xacro:base_link namex="base_link"/>

    <xacro:gear_link
        namex="driving_gear_link"
        mesh="package://gripper-rollpawkit/meshes/driving_gear.stl"/>
    <xacro:gear_joint
        namex="driving_gear_joint"
        parentx="base_link"
        childx="driving_gear_link"
        origin="0.0172 -0.0127 0.007"
        lo="-0.81"/>

    <xacro:gear_linkage_link
        namex="driving_linkage_link"
        mesh="package://gripper-rollpawkit/meshes/driven_linkage.stl"/>    
    <xacro:gear_linkage_joint
        namex="driving_linkage_joint"
        parentx="base_link"
        childx="driving_linkage_link"
        origin="0.0356 -0.0054 0.007"
        mimicx="driving_gear_joint"/>

    <xacro:finger_link
        namex="driving_finger_link"
        rpyx="0 0 0"
        mesh="package://gripper-rollpawkit/meshes/linkage.stl"/>    
    <xacro:finger_joint
        namex="driving_finger_joint"
        parentx="driving_gear_link"
        childx="driving_finger_link"
        origin="0.0308 0 0"
        lo="0.81"
        offset="0.42"
        mimicx="driving_gear_joint"/>
    
    <!-- -->

    <xacro:gear_link
        namex="driven_gear_link"
        mesh="package://gripper-rollpawkit/meshes/driven_gear.stl"/>
    <xacro:gear_joint
        namex="driven_gear_joint"
        parentx="base_link"
        childx="driven_gear_link"
        origin="0.0172 0.0127 0.007"
        hi="0.81"
        mimicx="driving_gear_joint"/>

    <xacro:gear_linkage_link
        namex="driven_linkage_link"
        mesh="package://gripper-rollpawkit/meshes/driven_linkage.stl"/>    
    <xacro:gear_linkage_joint
        namex="driven_linkage_joint"
        parentx="base_link"
        childx="driven_linkage_link"
        origin="0.0356 0.0054 0.007"
        mimicx="driven_gear_joint"/>

    <xacro:finger_link
        namex="driven_finger_link"
        rpyx="3.14 0 0"
        mesh="package://gripper-rollpawkit/meshes/linkage.stl"/>    
    <xacro:finger_joint
        namex="driven_finger_joint"
        parentx="driven_gear_link"
        childx="driven_finger_link"
        origin="0.0308 0 0"
        hi="0.81"
        offset="-0.42"
        mimicx="driven_gear_joint"/>

  </xacro:macro>

</robot>
